<sdf version='1.4'>
  <model name='base_robot'>
  	
    <link name='chassis'>
      <pose>0 0 0.08 0 0 0</pose>
      <collision name='collision'>
        <geometry>
          <box>
            <size>.4 .2 .1</size>
          </box>
        </geometry>
      </collision>

      <visual name='visual'>
        <geometry>
          <box>
            <size>.4 .2 .1</size>
          </box>
        </geometry>
      </visual>
    </link>
    <link name='leg_0_1'>
      <pose>0.12 -0.08 0 0 -0 0</pose>
      <inertial>
        <pose>0.01 -0.03 0 1.5708 -0 0</pose>
        <mass>0.02</mass>
        <inertia>
          <ixx>8e-06</ixx>
          <ixy>0</ixy>
          <ixz>0</ixz>
          <iyy>8e-06</iyy>
          <iyz>0</iyz>
          <izz>6.66667e-07</izz>
        </inertia>
      </inertial>
      <collision name='leg_0_1_collision'>
        <pose>0.01 -0.03 0 1.5708 -0 0</pose>
        <geometry>
          <cylinder>
            <length>0.06</length>
            <radius>0.02</radius>
          </cylinder>
        </geometry>
      </collision>
      <visual name='leg_0_1_visual'>
        <pose>0.01 -0.03 0 1.5708 -0 0</pose>
        <geometry>
          <cylinder>
            <length>0.06</length>
            <radius>0.02</radius>
          </cylinder>
        </geometry>
      </visual>
    </link>
    <joint name='body_leg_0' type='revolute'>
      <child>leg_0_1</child>
      <parent>chassis</parent>
      <axis>
        <xyz>0 0 1</xyz>
        <limit>
          <lower>-0.785398</lower>
          <upper>0.785398</upper>
          <effort>20</effort>
          <velocity>2</velocity>
        </limit>
        <dynamics>
          <spring_reference>0</spring_reference>
          <spring_stiffness>0</spring_stiffness>
        </dynamics>
        <use_parent_model_frame>1</use_parent_model_frame>
      </axis>
    </joint>

    <link name='leg_1_1'>
      <pose>-0.01 -0.08 0 0 -0 0</pose>
      <inertial>
        <pose>0.01 -0.03 0 1.5708 -0 0</pose>
        <mass>0.02</mass>
        <inertia>
          <ixx>8e-06</ixx>
          <ixy>0</ixy>
          <ixz>0</ixz>
          <iyy>8e-06</iyy>
          <iyz>0</iyz>
          <izz>6.66667e-07</izz>
        </inertia>
      </inertial>
      <collision name='leg_1_1_collision'>
        <pose>0.01 -0.03 0 1.5708 -0 0</pose>
        <geometry>
          <cylinder>
            <length>0.06</length>
            <radius>0.02</radius>
          </cylinder>
        </geometry>
      </collision>
      <visual name='leg_1_1_visual'>
        <pose>0.01 -0.03 0 1.5708 -0 0</pose>
        <geometry>
          <cylinder>
            <length>0.06</length>
            <radius>0.02</radius>
          </cylinder>
        </geometry>
      </visual>
    </link>
    <joint name='body_leg_1' type='revolute'>
      <child>leg_1_1</child>
      <parent>chassis</parent>
      <axis>
        <xyz>0 0 1</xyz>
        <limit>
          <lower>-0.785398</lower>
          <upper>0.785398</upper>
          <effort>20</effort>
          <velocity>2</velocity>
        </limit>
        <dynamics>
          <spring_reference>0</spring_reference>
          <spring_stiffness>0</spring_stiffness>
        </dynamics>
        <use_parent_model_frame>1</use_parent_model_frame>
      </axis>
    </joint>

    <link name='leg_2_1'>
      <pose>-0.14 -0.08 0 0 -0 0</pose>
      <inertial>
        <pose>0.01 -0.03 0 1.5708 -0 0</pose>
        <mass>0.02</mass>
        <inertia>
          <ixx>8e-06</ixx>
          <ixy>0</ixy>
          <ixz>0</ixz>
          <iyy>8e-06</iyy>
          <iyz>0</iyz>
          <izz>6.66667e-07</izz>
        </inertia>
      </inertial>
      <collision name='leg_2_1_collision'>
        <pose>0.01 -0.03 0 1.5708 -0 0</pose>
        <geometry>
          <cylinder>
            <length>0.06</length>
            <radius>0.02</radius>
          </cylinder>
        </geometry>
      </collision>
      <visual name='leg_2_1_visual'>
        <pose>0.01 -0.03 0 1.5708 -0 0</pose>
        <geometry>
          <cylinder>
            <length>0.06</length>
            <radius>0.02</radius>
          </cylinder>
        </geometry>
      </visual>
    </link>
    <joint name='body_leg_2' type='revolute'>
      <child>leg_2_1</child>
      <parent>chassis</parent>
      <axis>
        <xyz>0 0 1</xyz>
        <limit>
          <lower>-0.785398</lower>
          <upper>0.785398</upper>
          <effort>20</effort>
          <velocity>2</velocity>
        </limit>
        <dynamics>
          <spring_reference>0</spring_reference>
          <spring_stiffness>0</spring_stiffness>
        </dynamics>
        <use_parent_model_frame>1</use_parent_model_frame>
      </axis>
    </joint>

    <link name='leg_3_1'>
      <pose>-0.14 0.08 0 0 -0 0</pose>
      <inertial>
        <pose>0.01 0.03 0 1.5708 -0 0</pose>
        <mass>0.02</mass>
        <inertia>
          <ixx>8e-06</ixx>
          <ixy>0</ixy>
          <ixz>0</ixz>
          <iyy>8e-06</iyy>
          <iyz>0</iyz>
          <izz>6.66667e-07</izz>
        </inertia>
      </inertial>
      <collision name='leg_3_1_collision'>
        <pose>0.01 0.03 0 1.5708 -0 0</pose>
        <geometry>
          <cylinder>
            <length>0.06</length>
            <radius>0.02</radius>
          </cylinder>
        </geometry>
      </collision>
      <visual name='leg_3_1_visual'>
        <pose>0.01 0.03 0 1.5708 -0 0</pose>
        <geometry>
          <cylinder>
            <length>0.06</length>
            <radius>0.02</radius>
          </cylinder>
        </geometry>
      </visual>
    </link>
    <joint name='body_leg_3' type='revolute'>
      <child>leg_3_1</child>
      <parent>chassis</parent>
      <axis>
        <xyz>0 0 1</xyz>
        <limit>
          <lower>-0.785398</lower>
          <upper>0.785398</upper>
          <effort>20</effort>
          <velocity>2</velocity>
        </limit>
        <dynamics>
          <spring_reference>0</spring_reference>
          <spring_stiffness>0</spring_stiffness>
        </dynamics>
        <use_parent_model_frame>1</use_parent_model_frame>
      </axis>
    </joint>

    <link name='leg_4_1'>
      <pose>-0.01 0.08 0 0 -0 0</pose>
      <inertial>
        <pose>0.01 0.03 0 1.5708 -0 0</pose>
        <mass>0.02</mass>
        <inertia>
          <ixx>8e-06</ixx>
          <ixy>0</ixy>
          <ixz>0</ixz>
          <iyy>8e-06</iyy>
          <iyz>0</iyz>
          <izz>6.66667e-07</izz>
        </inertia>
      </inertial>
      <collision name='leg_4_1_collision'>
        <pose>0.01 0.03 0 1.5708 -0 0</pose>
        <geometry>
          <cylinder>
            <length>0.06</length>
            <radius>0.02</radius>
          </cylinder>
        </geometry>
      </collision>
      <visual name='leg_4_1_visual'>
        <pose>0.01 0.03 0 1.5708 -0 0</pose>
        <geometry>
          <cylinder>
            <length>0.06</length>
            <radius>0.02</radius>
          </cylinder>
        </geometry>
      </visual>
    </link>
    <joint name='body_leg_4' type='revolute'>
      <child>leg_4_1</child>
      <parent>chassis</parent>
      <axis>
        <xyz>0 0 1</xyz>
        <limit>
          <lower>-0.785398</lower>
          <upper>0.785398</upper>
          <effort>20</effort>
          <velocity>2</velocity>
        </limit>
        <dynamics>
          <spring_reference>0</spring_reference>
          <spring_stiffness>0</spring_stiffness>
        </dynamics>
        <use_parent_model_frame>1</use_parent_model_frame>
      </axis>
    </joint>

    <link name='leg_5_1'>
      <pose>0.12 0.08 0 0 -0 0</pose>
      <inertial>
        <pose>0.01 0.03 0 1.5708 -0 0</pose>
        <mass>0.02</mass>
        <inertia>
          <ixx>8e-06</ixx>
          <ixy>0</ixy>
          <ixz>0</ixz>
          <iyy>8e-06</iyy>
          <iyz>0</iyz>
          <izz>6.66667e-07</izz>
        </inertia>
      </inertial>
      <collision name='leg_5_1_collision'>
        <pose>0.01 0.03 0 1.5708 -0 0</pose>
        <geometry>
          <cylinder>
            <length>0.06</length>
            <radius>0.02</radius>
          </cylinder>
        </geometry>
      </collision>
      <visual name='leg_5_1_visual'>
        <pose>0.01 0.03 0 1.5708 -0 0</pose>
        <geometry>
          <cylinder>
            <length>0.06</length>
            <radius>0.02</radius>
          </cylinder>
        </geometry>
      </visual>
    </link>
    <joint name='body_leg_5' type='revolute'>
      <child>leg_5_1</child>
      <parent>chassis</parent>
      <axis>
        <xyz>0 0 1</xyz>
        <limit>
          <lower>-0.785398</lower>
          <upper>0.785398</upper>
          <effort>20</effort>
          <velocity>2</velocity>
        </limit>
        <dynamics>
          <spring_reference>0</spring_reference>
          <spring_stiffness>0</spring_stiffness>
        </dynamics>
        <use_parent_model_frame>1</use_parent_model_frame>
      </axis>
    </joint>
  </model>
</sdf>